WARNING:root:Failed to download from `https://omnipathdb.org/`.
WARNING:root:Traceback (most recent call last):
  File "/home/aih/sebastian.birk/miniconda3/envs/nichecompass-reproducibility/lib/python3.9/site-packages/urllib3/connectionpool.py", line 404, in _make_request
    self._validate_conn(conn)
  File "/home/aih/sebastian.birk/miniconda3/envs/nichecompass-reproducibility/lib/python3.9/site-packages/urllib3/connectionpool.py", line 1060, in _validate_conn
    conn.connect()
  File "/home/aih/sebastian.birk/miniconda3/envs/nichecompass-reproducibility/lib/python3.9/site-packages/urllib3/connection.py", line 419, in connect
    self.sock = ssl_wrap_socket(
  File "/home/aih/sebastian.birk/miniconda3/envs/nichecompass-reproducibility/lib/python3.9/site-packages/urllib3/util/ssl_.py", line 449, in ssl_wrap_socket
    ssl_sock = _ssl_wrap_socket_impl(
  File "/home/aih/sebastian.birk/miniconda3/envs/nichecompass-reproducibility/lib/python3.9/site-packages/urllib3/util/ssl_.py", line 493, in _ssl_wrap_socket_impl
    return ssl_context.wrap_socket(sock, server_hostname=server_hostname)
  File "/home/aih/sebastian.birk/miniconda3/envs/nichecompass-reproducibility/lib/python3.9/ssl.py", line 501, in wrap_socket
    return self.sslsocket_class._create(
  File "/home/aih/sebastian.birk/miniconda3/envs/nichecompass-reproducibility/lib/python3.9/ssl.py", line 1074, in _create
    self.do_handshake()
  File "/home/aih/sebastian.birk/miniconda3/envs/nichecompass-reproducibility/lib/python3.9/ssl.py", line 1343, in do_handshake
    self._sslobj.do_handshake()
socket.timeout: _ssl.c:1116: The handshake operation timed out

During handling of the above exception, another exception occurred:

Traceback (most recent call last):
  File "/home/aih/sebastian.birk/miniconda3/envs/nichecompass-reproducibility/lib/python3.9/site-packages/requests/adapters.py", line 667, in send
    resp = conn.urlopen(
  File "/home/aih/sebastian.birk/miniconda3/envs/nichecompass-reproducibility/lib/python3.9/site-packages/urllib3/connectionpool.py", line 801, in urlopen
    retries = retries.increment(
  File "/home/aih/sebastian.birk/miniconda3/envs/nichecompass-reproducibility/lib/python3.9/site-packages/urllib3/util/retry.py", line 552, in increment
    raise six.reraise(type(error), error, _stacktrace)
  File "/home/aih/sebastian.birk/miniconda3/envs/nichecompass-reproducibility/lib/python3.9/site-packages/urllib3/packages/six.py", line 770, in reraise
    raise value
  File "/home/aih/sebastian.birk/miniconda3/envs/nichecompass-reproducibility/lib/python3.9/site-packages/urllib3/connectionpool.py", line 715, in urlopen
    httplib_response = self._make_request(
  File "/home/aih/sebastian.birk/miniconda3/envs/nichecompass-reproducibility/lib/python3.9/site-packages/urllib3/connectionpool.py", line 407, in _make_request
    self._raise_timeout(err=e, url=url, timeout_value=conn.timeout)
  File "/home/aih/sebastian.birk/miniconda3/envs/nichecompass-reproducibility/lib/python3.9/site-packages/urllib3/connectionpool.py", line 358, in _raise_timeout
    raise ReadTimeoutError(
urllib3.exceptions.ReadTimeoutError: HTTPSConnectionPool(host='omnipathdb.org', port=443): Read timed out. (read timeout=3.0)

During handling of the above exception, another exception occurred:

Traceback (most recent call last):
  File "/home/aih/sebastian.birk/miniconda3/envs/nichecompass-reproducibility/lib/python3.9/site-packages/omnipath/_core/downloader/_downloader.py", line 143, in maybe_download
    res = self._download(req)
  File "/home/aih/sebastian.birk/miniconda3/envs/nichecompass-reproducibility/lib/python3.9/site-packages/omnipath/_core/downloader/_downloader.py", line 178, in _download
    with self._session.send(
  File "/home/aih/sebastian.birk/miniconda3/envs/nichecompass-reproducibility/lib/python3.9/site-packages/requests/sessions.py", line 703, in send
    r = adapter.send(request, **kwargs)
  File "/home/aih/sebastian.birk/miniconda3/envs/nichecompass-reproducibility/lib/python3.9/site-packages/requests/adapters.py", line 713, in send
    raise ReadTimeout(e, request=request)
requests.exceptions.ReadTimeout: HTTPSConnectionPool(host='omnipathdb.org', port=443): Read timed out. (read timeout=3.0)

WARNING:root:Failed to download from `https://omnipathdb.org/`.
WARNING:root:Traceback (most recent call last):
  File "/home/aih/sebastian.birk/miniconda3/envs/nichecompass-reproducibility/lib/python3.9/site-packages/urllib3/connection.py", line 174, in _new_conn
    conn = connection.create_connection(
  File "/home/aih/sebastian.birk/miniconda3/envs/nichecompass-reproducibility/lib/python3.9/site-packages/urllib3/util/connection.py", line 95, in create_connection
    raise err
  File "/home/aih/sebastian.birk/miniconda3/envs/nichecompass-reproducibility/lib/python3.9/site-packages/urllib3/util/connection.py", line 85, in create_connection
    sock.connect(sa)
socket.timeout: timed out

During handling of the above exception, another exception occurred:

Traceback (most recent call last):
  File "/home/aih/sebastian.birk/miniconda3/envs/nichecompass-reproducibility/lib/python3.9/site-packages/urllib3/connectionpool.py", line 715, in urlopen
    httplib_response = self._make_request(
  File "/home/aih/sebastian.birk/miniconda3/envs/nichecompass-reproducibility/lib/python3.9/site-packages/urllib3/connectionpool.py", line 404, in _make_request
    self._validate_conn(conn)
  File "/home/aih/sebastian.birk/miniconda3/envs/nichecompass-reproducibility/lib/python3.9/site-packages/urllib3/connectionpool.py", line 1060, in _validate_conn
    conn.connect()
  File "/home/aih/sebastian.birk/miniconda3/envs/nichecompass-reproducibility/lib/python3.9/site-packages/urllib3/connection.py", line 363, in connect
    self.sock = conn = self._new_conn()
  File "/home/aih/sebastian.birk/miniconda3/envs/nichecompass-reproducibility/lib/python3.9/site-packages/urllib3/connection.py", line 179, in _new_conn
    raise ConnectTimeoutError(
urllib3.exceptions.ConnectTimeoutError: (<urllib3.connection.HTTPSConnection object at 0x7efb8a228550>, 'Connection to omnipathdb.org timed out. (connect timeout=3.0)')

During handling of the above exception, another exception occurred:

Traceback (most recent call last):
  File "/home/aih/sebastian.birk/miniconda3/envs/nichecompass-reproducibility/lib/python3.9/site-packages/requests/adapters.py", line 667, in send
    resp = conn.urlopen(
  File "/home/aih/sebastian.birk/miniconda3/envs/nichecompass-reproducibility/lib/python3.9/site-packages/urllib3/connectionpool.py", line 801, in urlopen
    retries = retries.increment(
  File "/home/aih/sebastian.birk/miniconda3/envs/nichecompass-reproducibility/lib/python3.9/site-packages/urllib3/util/retry.py", line 594, in increment
    raise MaxRetryError(_pool, url, error or ResponseError(cause))
urllib3.exceptions.MaxRetryError: HTTPSConnectionPool(host='omnipathdb.org', port=443): Max retries exceeded with url: /queries/intercell?format=json (Caused by ConnectTimeoutError(<urllib3.connection.HTTPSConnection object at 0x7efb8a228550>, 'Connection to omnipathdb.org timed out. (connect timeout=3.0)'))

During handling of the above exception, another exception occurred:

Traceback (most recent call last):
  File "/home/aih/sebastian.birk/miniconda3/envs/nichecompass-reproducibility/lib/python3.9/site-packages/omnipath/_core/downloader/_downloader.py", line 143, in maybe_download
    res = self._download(req)
  File "/home/aih/sebastian.birk/miniconda3/envs/nichecompass-reproducibility/lib/python3.9/site-packages/omnipath/_core/downloader/_downloader.py", line 178, in _download
    with self._session.send(
  File "/home/aih/sebastian.birk/miniconda3/envs/nichecompass-reproducibility/lib/python3.9/site-packages/requests/sessions.py", line 703, in send
    r = adapter.send(request, **kwargs)
  File "/home/aih/sebastian.birk/miniconda3/envs/nichecompass-reproducibility/lib/python3.9/site-packages/requests/adapters.py", line 688, in send
    raise ConnectTimeout(e, request=request)
requests.exceptions.ConnectTimeout: HTTPSConnectionPool(host='omnipathdb.org', port=443): Max retries exceeded with url: /queries/intercell?format=json (Caused by ConnectTimeoutError(<urllib3.connection.HTTPSConnection object at 0x7efb8a228550>, 'Connection to omnipathdb.org timed out. (connect timeout=3.0)'))

/home/aih/sebastian.birk/miniconda3/envs/nichecompass-reproducibility/lib/python3.9/site-packages/nichecompass/utils/gene_programs.py:506: FutureWarning: DataFrame.applymap has been deprecated. Use DataFrame.map instead.
  ligand_target_matrix_df.applymap(
/home/aih/sebastian.birk/miniconda3/envs/nichecompass-reproducibility/lib/python3.9/site-packages/torch/cuda/__init__.py:173: UserWarning: 
NVIDIA H100 80GB HBM3 with CUDA capability sm_90 is not compatible with the current PyTorch installation.
The current PyTorch install supports CUDA capabilities sm_37 sm_50 sm_60 sm_61 sm_70 sm_75 sm_80 sm_86 compute_37.
If you want to use the NVIDIA H100 80GB HBM3 GPU with PyTorch, please check the instructions at https://pytorch.org/get-started/locally/

  warnings.warn(incompatible_device_warn.format(device_name, capability, " ".join(arch_list), device_name))
/home/aih/sebastian.birk/miniconda3/envs/nichecompass-reproducibility/lib/python3.9/site-packages/torch_geometric/sampler/neighbor_sampler.py:55: UserWarning: The usage of the 'directed' argument in 'NeighborSampler' is deprecated. Use `subgraph_type='induced'` instead.
  warnings.warn(f"The usage of the 'directed' argument in "
/home/aih/sebastian.birk/miniconda3/envs/nichecompass-reproducibility/lib/python3.9/site-packages/torch_geometric/sampler/neighbor_sampler.py:55: UserWarning: The usage of the 'directed' argument in 'NeighborSampler' is deprecated. Use `subgraph_type='induced'` instead.
  warnings.warn(f"The usage of the 'directed' argument in "
