WARNING:root:Failed to download from `https://omnipathdb.org/`.
WARNING:root:Traceback (most recent call last):
  File "/home/aih/sebastian.birk/miniconda3/envs/nichecompass-reproducibility/lib/python3.9/site-packages/urllib3/connection.py", line 174, in _new_conn
    conn = connection.create_connection(
  File "/home/aih/sebastian.birk/miniconda3/envs/nichecompass-reproducibility/lib/python3.9/site-packages/urllib3/util/connection.py", line 95, in create_connection
    raise err
  File "/home/aih/sebastian.birk/miniconda3/envs/nichecompass-reproducibility/lib/python3.9/site-packages/urllib3/util/connection.py", line 85, in create_connection
    sock.connect(sa)
socket.timeout: timed out

During handling of the above exception, another exception occurred:

Traceback (most recent call last):
  File "/home/aih/sebastian.birk/miniconda3/envs/nichecompass-reproducibility/lib/python3.9/site-packages/urllib3/connectionpool.py", line 715, in urlopen
    httplib_response = self._make_request(
  File "/home/aih/sebastian.birk/miniconda3/envs/nichecompass-reproducibility/lib/python3.9/site-packages/urllib3/connectionpool.py", line 404, in _make_request
    self._validate_conn(conn)
  File "/home/aih/sebastian.birk/miniconda3/envs/nichecompass-reproducibility/lib/python3.9/site-packages/urllib3/connectionpool.py", line 1060, in _validate_conn
    conn.connect()
  File "/home/aih/sebastian.birk/miniconda3/envs/nichecompass-reproducibility/lib/python3.9/site-packages/urllib3/connection.py", line 363, in connect
    self.sock = conn = self._new_conn()
  File "/home/aih/sebastian.birk/miniconda3/envs/nichecompass-reproducibility/lib/python3.9/site-packages/urllib3/connection.py", line 179, in _new_conn
    raise ConnectTimeoutError(
urllib3.exceptions.ConnectTimeoutError: (<urllib3.connection.HTTPSConnection object at 0x7fc2797956a0>, 'Connection to omnipathdb.org timed out. (connect timeout=3.0)')

During handling of the above exception, another exception occurred:

Traceback (most recent call last):
  File "/home/aih/sebastian.birk/miniconda3/envs/nichecompass-reproducibility/lib/python3.9/site-packages/requests/adapters.py", line 667, in send
    resp = conn.urlopen(
  File "/home/aih/sebastian.birk/miniconda3/envs/nichecompass-reproducibility/lib/python3.9/site-packages/urllib3/connectionpool.py", line 801, in urlopen
    retries = retries.increment(
  File "/home/aih/sebastian.birk/miniconda3/envs/nichecompass-reproducibility/lib/python3.9/site-packages/urllib3/util/retry.py", line 594, in increment
    raise MaxRetryError(_pool, url, error or ResponseError(cause))
urllib3.exceptions.MaxRetryError: HTTPSConnectionPool(host='omnipathdb.org', port=443): Max retries exceeded with url: /queries/enzsub?format=json (Caused by ConnectTimeoutError(<urllib3.connection.HTTPSConnection object at 0x7fc2797956a0>, 'Connection to omnipathdb.org timed out. (connect timeout=3.0)'))

During handling of the above exception, another exception occurred:

Traceback (most recent call last):
  File "/home/aih/sebastian.birk/miniconda3/envs/nichecompass-reproducibility/lib/python3.9/site-packages/omnipath/_core/downloader/_downloader.py", line 143, in maybe_download
    res = self._download(req)
  File "/home/aih/sebastian.birk/miniconda3/envs/nichecompass-reproducibility/lib/python3.9/site-packages/omnipath/_core/downloader/_downloader.py", line 178, in _download
    with self._session.send(
  File "/home/aih/sebastian.birk/miniconda3/envs/nichecompass-reproducibility/lib/python3.9/site-packages/requests/sessions.py", line 703, in send
    r = adapter.send(request, **kwargs)
  File "/home/aih/sebastian.birk/miniconda3/envs/nichecompass-reproducibility/lib/python3.9/site-packages/requests/adapters.py", line 688, in send
    raise ConnectTimeout(e, request=request)
requests.exceptions.ConnectTimeout: HTTPSConnectionPool(host='omnipathdb.org', port=443): Max retries exceeded with url: /queries/enzsub?format=json (Caused by ConnectTimeoutError(<urllib3.connection.HTTPSConnection object at 0x7fc2797956a0>, 'Connection to omnipathdb.org timed out. (connect timeout=3.0)'))

/home/aih/sebastian.birk/miniconda3/envs/nichecompass-reproducibility/lib/python3.9/site-packages/nichecompass/utils/gene_programs.py:506: FutureWarning: DataFrame.applymap has been deprecated. Use DataFrame.map instead.
  ligand_target_matrix_df.applymap(
/home/aih/sebastian.birk/miniconda3/envs/nichecompass-reproducibility/lib/python3.9/site-packages/torch_geometric/sampler/neighbor_sampler.py:55: UserWarning: The usage of the 'directed' argument in 'NeighborSampler' is deprecated. Use `subgraph_type='induced'` instead.
  warnings.warn(f"The usage of the 'directed' argument in "
/home/aih/sebastian.birk/miniconda3/envs/nichecompass-reproducibility/lib/python3.9/site-packages/torch_geometric/sampler/neighbor_sampler.py:55: UserWarning: The usage of the 'directed' argument in 'NeighborSampler' is deprecated. Use `subgraph_type='induced'` instead.
  warnings.warn(f"The usage of the 'directed' argument in "
